2024-09-29 14:36:38,443 INFO    StreamThr :20028 [internal.py:wandb_internal():85] W&B internal server running at pid: 20028, started at: 2024-09-29 14:36:38.442633
2024-09-29 14:36:38,444 DEBUG   HandlerThread:20028 [handler.py:handle_request():158] handle_request: status
2024-09-29 14:36:38,467 INFO    WriterThread:20028 [datastore.py:open_for_write():87] open: /home/egor/desktop/tmp/precondnn/exps/loss_choice_exps/exp02/wandb/run-20240929_143638-qt2c1omz/run-qt2c1omz.wandb
2024-09-29 14:36:38,472 DEBUG   SenderThread:20028 [sender.py:send():391] send: header
2024-09-29 14:36:38,497 DEBUG   SenderThread:20028 [sender.py:send():391] send: run
2024-09-29 14:36:39,124 INFO    SenderThread:20028 [dir_watcher.py:__init__():211] watching files in: /home/egor/desktop/tmp/precondnn/exps/loss_choice_exps/exp02/wandb/run-20240929_143638-qt2c1omz/files
2024-09-29 14:36:39,124 INFO    SenderThread:20028 [sender.py:_start_run_threads():1200] run started: qt2c1omz with start time 1727609798.442804
2024-09-29 14:36:39,136 DEBUG   HandlerThread:20028 [handler.py:handle_request():158] handle_request: run_start
2024-09-29 14:36:39,137 DEBUG   HandlerThread:20028 [system_info.py:__init__():26] System info init
2024-09-29 14:36:39,137 DEBUG   HandlerThread:20028 [system_info.py:__init__():41] System info init done
2024-09-29 14:36:39,137 INFO    HandlerThread:20028 [system_monitor.py:start():194] Starting system monitor
2024-09-29 14:36:39,137 INFO    SystemMonitor:20028 [system_monitor.py:_start():158] Starting system asset monitoring threads
2024-09-29 14:36:39,137 INFO    HandlerThread:20028 [system_monitor.py:probe():214] Collecting system info
2024-09-29 14:36:39,138 INFO    SystemMonitor:20028 [interfaces.py:start():188] Started cpu monitoring
2024-09-29 14:36:39,139 INFO    SystemMonitor:20028 [interfaces.py:start():188] Started disk monitoring
2024-09-29 14:36:39,139 INFO    SystemMonitor:20028 [interfaces.py:start():188] Started memory monitoring
2024-09-29 14:36:39,140 INFO    SystemMonitor:20028 [interfaces.py:start():188] Started network monitoring
2024-09-29 14:36:39,161 DEBUG   HandlerThread:20028 [system_info.py:probe():152] Probing system
2024-09-29 14:36:39,163 DEBUG   HandlerThread:20028 [system_info.py:_probe_git():137] Probing git
2024-09-29 14:36:39,169 DEBUG   HandlerThread:20028 [system_info.py:_probe_git():145] Probing git done
2024-09-29 14:36:39,169 DEBUG   HandlerThread:20028 [system_info.py:probe():200] Probing system done
2024-09-29 14:36:39,169 DEBUG   HandlerThread:20028 [system_monitor.py:probe():223] {'os': 'Linux-5.15.0-88-generic-x86_64-with-glibc2.35', 'python': '3.11.5', 'heartbeatAt': '2024-09-29T11:36:39.161529', 'startedAt': '2024-09-29T11:36:38.435153', 'docker': None, 'cuda': None, 'args': (), 'state': 'running', 'program': 'main.ipynb', 'codePathLocal': 'main.ipynb', 'root': '/home/egor/desktop/tmp/precondnn', 'git': {'remote': 'git@github.com:e1vanov/precondnn.git', 'commit': 'b80f5b6636af1f2441be2fb5337e774b15d2a187'}, 'email': 's02210401@gse.cs.msu.ru', 'host': 'egor-MacBookAir', 'username': 'egor', 'executable': '/home/egor/miniconda3/bin/python', 'cpu_count': 2, 'cpu_count_logical': 4, 'cpu_freq': {'current': 2.151, 'min': 500.0, 'max': 2900.0}, 'cpu_freq_per_core': [{'current': 1.8, 'min': 500.0, 'max': 2900.0}, {'current': 1.904, 'min': 500.0, 'max': 2900.0}, {'current': 2.1, 'min': 500.0, 'max': 2900.0}, {'current': 2.8, 'min': 500.0, 'max': 2900.0}], 'disk': {'/': {'total': 457.2810821533203, 'used': 57.58797836303711}}, 'memory': {'total': 7.656715393066406}}
2024-09-29 14:36:39,169 INFO    HandlerThread:20028 [system_monitor.py:probe():224] Finished collecting system info
2024-09-29 14:36:39,169 INFO    HandlerThread:20028 [system_monitor.py:probe():227] Publishing system info
2024-09-29 14:36:39,170 DEBUG   HandlerThread:20028 [system_info.py:_save_conda():209] Saving list of conda packages installed into the current environment
2024-09-29 14:36:40,126 INFO    Thread-12 :20028 [dir_watcher.py:_on_file_created():271] file/dir created: /home/egor/desktop/tmp/precondnn/exps/loss_choice_exps/exp02/wandb/run-20240929_143638-qt2c1omz/files/conda-environment.yaml
2024-09-29 14:36:43,342 DEBUG   HandlerThread:20028 [system_info.py:_save_conda():224] Saving conda packages done
2024-09-29 14:36:43,343 INFO    HandlerThread:20028 [system_monitor.py:probe():229] Finished publishing system info
2024-09-29 14:36:43,345 DEBUG   SenderThread:20028 [sender.py:send():391] send: files
2024-09-29 14:36:43,346 INFO    SenderThread:20028 [sender.py:_save_file():1466] saving file wandb-metadata.json with policy now
2024-09-29 14:36:43,494 DEBUG   HandlerThread:20028 [handler.py:handle_request():158] handle_request: python_packages
2024-09-29 14:36:43,494 DEBUG   SenderThread:20028 [sender.py:send_request():418] send_request: python_packages
2024-09-29 14:36:43,494 DEBUG   HandlerThread:20028 [handler.py:handle_request():158] handle_request: stop_status
2024-09-29 14:36:43,495 DEBUG   SenderThread:20028 [sender.py:send_request():418] send_request: stop_status
2024-09-29 14:36:43,495 DEBUG   HandlerThread:20028 [handler.py:handle_request():158] handle_request: status_report
2024-09-29 14:36:43,497 DEBUG   HandlerThread:20028 [handler.py:handle_request():158] handle_request: internal_messages
2024-09-29 14:36:43,948 DEBUG   SenderThread:20028 [sender.py:send():391] send: telemetry
2024-09-29 14:36:44,125 INFO    Thread-12 :20028 [dir_watcher.py:_on_file_modified():288] file/dir modified: /home/egor/desktop/tmp/precondnn/exps/loss_choice_exps/exp02/wandb/run-20240929_143638-qt2c1omz/files/conda-environment.yaml
2024-09-29 14:36:44,126 INFO    Thread-12 :20028 [dir_watcher.py:_on_file_created():271] file/dir created: /home/egor/desktop/tmp/precondnn/exps/loss_choice_exps/exp02/wandb/run-20240929_143638-qt2c1omz/files/output.log
2024-09-29 14:36:44,126 INFO    Thread-12 :20028 [dir_watcher.py:_on_file_created():271] file/dir created: /home/egor/desktop/tmp/precondnn/exps/loss_choice_exps/exp02/wandb/run-20240929_143638-qt2c1omz/files/requirements.txt
2024-09-29 14:36:44,126 INFO    Thread-12 :20028 [dir_watcher.py:_on_file_created():271] file/dir created: /home/egor/desktop/tmp/precondnn/exps/loss_choice_exps/exp02/wandb/run-20240929_143638-qt2c1omz/files/wandb-metadata.json
2024-09-29 14:36:44,137 INFO    wandb-upload_0:20028 [upload_job.py:push():130] Uploaded file /tmp/tmpy1me130mwandb/o3j3xyck-wandb-metadata.json
2024-09-29 14:36:46,126 INFO    Thread-12 :20028 [dir_watcher.py:_on_file_modified():288] file/dir modified: /home/egor/desktop/tmp/precondnn/exps/loss_choice_exps/exp02/wandb/run-20240929_143638-qt2c1omz/files/output.log
2024-09-29 14:36:48,127 INFO    Thread-12 :20028 [dir_watcher.py:_on_file_modified():288] file/dir modified: /home/egor/desktop/tmp/precondnn/exps/loss_choice_exps/exp02/wandb/run-20240929_143638-qt2c1omz/files/output.log
2024-09-29 14:36:48,497 DEBUG   HandlerThread:20028 [handler.py:handle_request():158] handle_request: status_report
2024-09-29 14:36:48,966 DEBUG   HandlerThread:20028 [handler.py:handle_request():158] handle_request: pause
2024-09-29 14:36:48,966 INFO    HandlerThread:20028 [handler.py:handle_request_pause():728] stopping system metrics thread
2024-09-29 14:36:48,966 INFO    HandlerThread:20028 [system_monitor.py:finish():203] Stopping system monitor
2024-09-29 14:36:48,966 INFO    HandlerThread:20028 [interfaces.py:finish():200] Joined cpu monitor
2024-09-29 14:36:48,967 DEBUG   SystemMonitor:20028 [system_monitor.py:_start():172] Starting system metrics aggregation loop
2024-09-29 14:36:48,967 DEBUG   SystemMonitor:20028 [system_monitor.py:_start():179] Finished system metrics aggregation loop
2024-09-29 14:36:48,967 DEBUG   SystemMonitor:20028 [system_monitor.py:_start():183] Publishing last batch of metrics
2024-09-29 14:36:48,967 INFO    HandlerThread:20028 [interfaces.py:finish():200] Joined disk monitor
2024-09-29 14:36:48,968 INFO    HandlerThread:20028 [interfaces.py:finish():200] Joined memory monitor
2024-09-29 14:36:48,968 INFO    HandlerThread:20028 [interfaces.py:finish():200] Joined network monitor
2024-09-29 14:36:48,969 DEBUG   SenderThread:20028 [sender.py:send():391] send: stats
2024-09-29 14:36:53,496 DEBUG   HandlerThread:20028 [handler.py:handle_request():158] handle_request: internal_messages
2024-09-29 14:36:53,497 DEBUG   HandlerThread:20028 [handler.py:handle_request():158] handle_request: status_report
2024-09-29 14:36:58,494 DEBUG   HandlerThread:20028 [handler.py:handle_request():158] handle_request: stop_status
2024-09-29 14:36:58,495 DEBUG   SenderThread:20028 [sender.py:send_request():418] send_request: stop_status
2024-09-29 14:36:58,722 DEBUG   HandlerThread:20028 [handler.py:handle_request():158] handle_request: status_report
2024-09-29 14:37:03,495 DEBUG   HandlerThread:20028 [handler.py:handle_request():158] handle_request: internal_messages
2024-09-29 14:37:04,497 DEBUG   HandlerThread:20028 [handler.py:handle_request():158] handle_request: status_report
2024-09-29 14:37:09,511 DEBUG   HandlerThread:20028 [handler.py:handle_request():158] handle_request: status_report
2024-09-29 14:37:10,139 INFO    Thread-12 :20028 [dir_watcher.py:_on_file_modified():288] file/dir modified: /home/egor/desktop/tmp/precondnn/exps/loss_choice_exps/exp02/wandb/run-20240929_143638-qt2c1omz/files/config.yaml
2024-09-29 14:37:13,494 DEBUG   HandlerThread:20028 [handler.py:handle_request():158] handle_request: stop_status
2024-09-29 14:37:13,495 DEBUG   SenderThread:20028 [sender.py:send_request():418] send_request: stop_status
2024-09-29 14:37:13,535 DEBUG   HandlerThread:20028 [handler.py:handle_request():158] handle_request: internal_messages
2024-09-29 14:37:15,716 DEBUG   HandlerThread:20028 [handler.py:handle_request():158] handle_request: status_report
2024-09-29 14:37:21,497 DEBUG   HandlerThread:20028 [handler.py:handle_request():158] handle_request: status_report
2024-09-29 14:37:23,495 DEBUG   HandlerThread:20028 [handler.py:handle_request():158] handle_request: internal_messages
2024-09-29 14:37:26,109 DEBUG   SenderThread:20028 [sender.py:send():391] send: exit
2024-09-29 14:37:26,109 INFO    SenderThread:20028 [sender.py:send_exit():598] handling exit code: 0
2024-09-29 14:37:26,110 INFO    SenderThread:20028 [sender.py:send_exit():600] handling runtime: 9
2024-09-29 14:37:26,111 INFO    SenderThread:20028 [sender.py:_save_file():1466] saving file wandb-summary.json with policy end
2024-09-29 14:37:26,112 INFO    SenderThread:20028 [sender.py:send_exit():606] send defer
2024-09-29 14:37:26,112 DEBUG   HandlerThread:20028 [handler.py:handle_request():158] handle_request: defer
2024-09-29 14:37:26,112 INFO    HandlerThread:20028 [handler.py:handle_request_defer():184] handle defer: 0
2024-09-29 14:37:26,112 DEBUG   SenderThread:20028 [sender.py:send_request():418] send_request: defer
2024-09-29 14:37:26,112 INFO    SenderThread:20028 [sender.py:send_request_defer():622] handle sender defer: 0
2024-09-29 14:37:26,112 INFO    SenderThread:20028 [sender.py:transition_state():626] send defer: 1
2024-09-29 14:37:26,113 DEBUG   HandlerThread:20028 [handler.py:handle_request():158] handle_request: defer
2024-09-29 14:37:26,113 INFO    HandlerThread:20028 [handler.py:handle_request_defer():184] handle defer: 1
2024-09-29 14:37:26,113 DEBUG   SenderThread:20028 [sender.py:send_request():418] send_request: defer
2024-09-29 14:37:26,113 INFO    SenderThread:20028 [sender.py:send_request_defer():622] handle sender defer: 1
2024-09-29 14:37:26,113 INFO    SenderThread:20028 [sender.py:transition_state():626] send defer: 2
2024-09-29 14:37:26,113 DEBUG   HandlerThread:20028 [handler.py:handle_request():158] handle_request: defer
2024-09-29 14:37:26,113 INFO    HandlerThread:20028 [handler.py:handle_request_defer():184] handle defer: 2
2024-09-29 14:37:26,113 DEBUG   SenderThread:20028 [sender.py:send_request():418] send_request: defer
2024-09-29 14:37:26,114 INFO    SenderThread:20028 [sender.py:send_request_defer():622] handle sender defer: 2
2024-09-29 14:37:26,114 INFO    SenderThread:20028 [sender.py:transition_state():626] send defer: 3
2024-09-29 14:37:26,114 DEBUG   HandlerThread:20028 [handler.py:handle_request():158] handle_request: defer
2024-09-29 14:37:26,114 INFO    HandlerThread:20028 [handler.py:handle_request_defer():184] handle defer: 3
2024-09-29 14:37:26,114 DEBUG   SenderThread:20028 [sender.py:send_request():418] send_request: defer
2024-09-29 14:37:26,114 INFO    SenderThread:20028 [sender.py:send_request_defer():622] handle sender defer: 3
2024-09-29 14:37:26,114 INFO    SenderThread:20028 [sender.py:transition_state():626] send defer: 4
2024-09-29 14:37:26,114 DEBUG   HandlerThread:20028 [handler.py:handle_request():158] handle_request: defer
2024-09-29 14:37:26,114 INFO    HandlerThread:20028 [handler.py:handle_request_defer():184] handle defer: 4
2024-09-29 14:37:26,115 DEBUG   SenderThread:20028 [sender.py:send_request():418] send_request: defer
2024-09-29 14:37:26,115 INFO    SenderThread:20028 [sender.py:send_request_defer():622] handle sender defer: 4
2024-09-29 14:37:26,115 INFO    SenderThread:20028 [sender.py:transition_state():626] send defer: 5
2024-09-29 14:37:26,115 DEBUG   HandlerThread:20028 [handler.py:handle_request():158] handle_request: defer
2024-09-29 14:37:26,115 INFO    HandlerThread:20028 [handler.py:handle_request_defer():184] handle defer: 5
2024-09-29 14:37:26,115 DEBUG   SenderThread:20028 [sender.py:send():391] send: summary
2024-09-29 14:37:26,116 INFO    SenderThread:20028 [sender.py:_save_file():1466] saving file wandb-summary.json with policy end
2024-09-29 14:37:26,116 DEBUG   SenderThread:20028 [sender.py:send_request():418] send_request: defer
2024-09-29 14:37:26,116 INFO    SenderThread:20028 [sender.py:send_request_defer():622] handle sender defer: 5
2024-09-29 14:37:26,116 INFO    SenderThread:20028 [sender.py:transition_state():626] send defer: 6
2024-09-29 14:37:26,116 DEBUG   HandlerThread:20028 [handler.py:handle_request():158] handle_request: defer
2024-09-29 14:37:26,116 INFO    HandlerThread:20028 [handler.py:handle_request_defer():184] handle defer: 6
2024-09-29 14:37:26,117 DEBUG   SenderThread:20028 [sender.py:send_request():418] send_request: defer
2024-09-29 14:37:26,117 INFO    SenderThread:20028 [sender.py:send_request_defer():622] handle sender defer: 6
2024-09-29 14:37:26,117 INFO    SenderThread:20028 [sender.py:transition_state():626] send defer: 7
2024-09-29 14:37:26,117 DEBUG   HandlerThread:20028 [handler.py:handle_request():158] handle_request: status_report
2024-09-29 14:37:26,117 DEBUG   HandlerThread:20028 [handler.py:handle_request():158] handle_request: defer
2024-09-29 14:37:26,117 INFO    HandlerThread:20028 [handler.py:handle_request_defer():184] handle defer: 7
2024-09-29 14:37:26,117 DEBUG   SenderThread:20028 [sender.py:send_request():418] send_request: defer
2024-09-29 14:37:26,118 INFO    SenderThread:20028 [sender.py:send_request_defer():622] handle sender defer: 7
2024-09-29 14:37:26,145 INFO    Thread-12 :20028 [dir_watcher.py:_on_file_created():271] file/dir created: /home/egor/desktop/tmp/precondnn/exps/loss_choice_exps/exp02/wandb/run-20240929_143638-qt2c1omz/files/wandb-summary.json
2024-09-29 14:37:26,289 ERROR   FileStreamThread:20028 [file_stream.py:_handle_response():510] dropped chunk 404 Client Error: Not Found for url: https://api.wandb.ai/files/cmcmsu/loss_choice_02/qt2c1omz/file_stream
NoneType: None
2024-09-29 14:37:27,109 DEBUG   HandlerThread:20028 [handler.py:handle_request():158] handle_request: poll_exit
2024-09-29 14:37:27,966 INFO    SenderThread:20028 [sender.py:transition_state():626] send defer: 8
2024-09-29 14:37:27,967 DEBUG   SenderThread:20028 [sender.py:send_request():418] send_request: poll_exit
2024-09-29 14:37:27,967 DEBUG   HandlerThread:20028 [handler.py:handle_request():158] handle_request: defer
2024-09-29 14:37:27,967 INFO    HandlerThread:20028 [handler.py:handle_request_defer():184] handle defer: 8
2024-09-29 14:37:27,968 DEBUG   SenderThread:20028 [sender.py:send_request():418] send_request: defer
2024-09-29 14:37:27,968 INFO    SenderThread:20028 [sender.py:send_request_defer():622] handle sender defer: 8
2024-09-29 14:37:27,969 INFO    SenderThread:20028 [job_builder.py:build():443] Attempting to build job artifact
2024-09-29 14:37:27,969 INFO    SenderThread:20028 [job_builder.py:_get_source_type():572] is repo sourced job
2024-09-29 14:37:27,969 INFO    SenderThread:20028 [job_builder.py:_get_program_relpath():590] run is notebook based run
2024-09-29 14:37:28,002 INFO    SenderThread:20028 [job_builder.py:build():548] adding wandb-job metadata file
2024-09-29 14:37:28,044 INFO    SenderThread:20028 [sender.py:transition_state():626] send defer: 9
2024-09-29 14:37:28,044 DEBUG   HandlerThread:20028 [handler.py:handle_request():158] handle_request: defer
2024-09-29 14:37:28,045 INFO    HandlerThread:20028 [handler.py:handle_request_defer():184] handle defer: 9
2024-09-29 14:37:28,045 DEBUG   SenderThread:20028 [sender.py:send():391] send: artifact
2024-09-29 14:37:28,111 DEBUG   HandlerThread:20028 [handler.py:handle_request():158] handle_request: poll_exit
2024-09-29 14:37:28,146 INFO    Thread-12 :20028 [dir_watcher.py:_on_file_modified():288] file/dir modified: /home/egor/desktop/tmp/precondnn/exps/loss_choice_exps/exp02/wandb/run-20240929_143638-qt2c1omz/files/output.log
2024-09-29 14:37:28,454 ERROR   FileStreamThread:20028 [file_stream.py:_thread_except_body():500] generic exception in filestream thread
Traceback (most recent call last):
  File "/home/egor/miniconda3/lib/python3.11/site-packages/wandb/sdk/internal/file_stream.py", line 496, in _thread_except_body
    self._thread_body()
  File "/home/egor/miniconda3/lib/python3.11/site-packages/wandb/sdk/internal/file_stream.py", line 452, in _thread_body
    success = self._send(ready_chunks, uploaded=uploaded)
              ^^^^^^^^^^^^^^^^^^^^^^^^^^^^^^^^^^^^^^^^^^^
  File "/home/egor/miniconda3/lib/python3.11/site-packages/wandb/sdk/internal/file_stream.py", line 541, in _send
    self._handle_response(
  File "/home/egor/miniconda3/lib/python3.11/site-packages/wandb/sdk/internal/file_stream.py", line 507, in _handle_response
    wandb.termerror(
  File "/home/egor/miniconda3/lib/python3.11/site-packages/wandb/errors/term.py", line 64, in termerror
    _log(
  File "/home/egor/miniconda3/lib/python3.11/site-packages/wandb/errors/term.py", line 103, in _log
    click.echo(line, file=sys.stderr, nl=newline)
  File "/home/egor/miniconda3/lib/python3.11/site-packages/click/utils.py", line 318, in echo
    file.write(out)  # type: ignore
    ^^^^^^^^^^^^^^^
BrokenPipeError: [Errno 32] Broken pipe
2024-09-29 14:37:28,776 ERROR   SenderThread:20028 [internal_api.py:execute():349] 404 response executing GraphQL.
2024-09-29 14:37:28,776 ERROR   SenderThread:20028 [internal_api.py:execute():350] {"errors":[{"message":"failed to find run loss_choice_02/qt2c1omz","path":["createArtifactManifest"]}],"data":{"createArtifactManifest":null}}
2024-09-29 14:37:28,777 ERROR   SenderThread:20028 [sender.py:send_artifact():1551] send_artifact: failed for artifact "job/job-git_github.com_e1vanov_precondnn.git_main.ipynb": [Errno 32] Broken pipe
2024-09-29 14:37:28,777 DEBUG   SenderThread:20028 [sender.py:send_request():418] send_request: defer
2024-09-29 14:37:28,777 INFO    SenderThread:20028 [sender.py:send_request_defer():622] handle sender defer: 9
2024-09-29 14:37:28,777 INFO    SenderThread:20028 [dir_watcher.py:finish():358] shutting down directory watcher
2024-09-29 14:37:29,147 INFO    SenderThread:20028 [dir_watcher.py:finish():388] scan: /home/egor/desktop/tmp/precondnn/exps/loss_choice_exps/exp02/wandb/run-20240929_143638-qt2c1omz/files
2024-09-29 14:37:29,147 INFO    SenderThread:20028 [dir_watcher.py:finish():402] scan save: /home/egor/desktop/tmp/precondnn/exps/loss_choice_exps/exp02/wandb/run-20240929_143638-qt2c1omz/files/output.log output.log
2024-09-29 14:37:29,147 INFO    SenderThread:20028 [dir_watcher.py:finish():402] scan save: /home/egor/desktop/tmp/precondnn/exps/loss_choice_exps/exp02/wandb/run-20240929_143638-qt2c1omz/files/wandb-summary.json wandb-summary.json
2024-09-29 14:37:29,148 INFO    SenderThread:20028 [dir_watcher.py:finish():402] scan save: /home/egor/desktop/tmp/precondnn/exps/loss_choice_exps/exp02/wandb/run-20240929_143638-qt2c1omz/files/config.yaml config.yaml
2024-09-29 14:37:29,152 INFO    SenderThread:20028 [dir_watcher.py:finish():402] scan save: /home/egor/desktop/tmp/precondnn/exps/loss_choice_exps/exp02/wandb/run-20240929_143638-qt2c1omz/files/requirements.txt requirements.txt
2024-09-29 14:37:29,155 INFO    SenderThread:20028 [dir_watcher.py:finish():402] scan save: /home/egor/desktop/tmp/precondnn/exps/loss_choice_exps/exp02/wandb/run-20240929_143638-qt2c1omz/files/conda-environment.yaml conda-environment.yaml
2024-09-29 14:37:29,155 INFO    SenderThread:20028 [dir_watcher.py:finish():402] scan save: /home/egor/desktop/tmp/precondnn/exps/loss_choice_exps/exp02/wandb/run-20240929_143638-qt2c1omz/files/wandb-metadata.json wandb-metadata.json
2024-09-29 14:37:29,157 INFO    SenderThread:20028 [sender.py:transition_state():626] send defer: 10
2024-09-29 14:37:29,159 DEBUG   SenderThread:20028 [sender.py:send_request():418] send_request: poll_exit
2024-09-29 14:37:29,159 DEBUG   HandlerThread:20028 [handler.py:handle_request():158] handle_request: defer
2024-09-29 14:37:29,160 INFO    HandlerThread:20028 [handler.py:handle_request_defer():184] handle defer: 10
2024-09-29 14:37:29,160 DEBUG   SenderThread:20028 [sender.py:send_request():418] send_request: defer
2024-09-29 14:37:29,160 INFO    SenderThread:20028 [sender.py:send_request_defer():622] handle sender defer: 10
2024-09-29 14:37:29,161 INFO    SenderThread:20028 [file_pusher.py:finish():169] shutting down file pusher
2024-09-29 14:37:29,320 ERROR   wandb-upload_0:20028 [internal_api.py:execute():349] 404 response executing GraphQL.
2024-09-29 14:37:29,320 ERROR   wandb-upload_0:20028 [internal_api.py:execute():350] {"errors":[{"message":"run loss_choice_02/qt2c1omz not found during createRunFiles","path":["createRunFiles"]}],"data":{"createRunFiles":null}}
2024-09-29 14:37:29,321 ERROR   Thread-11 (_thread_body):20028 [step_upload.py:_handle_event():144] Failed to upload file: /home/egor/desktop/tmp/precondnn/exps/loss_choice_exps/exp02/wandb/run-20240929_143638-qt2c1omz/files/output.log
Traceback (most recent call last):
  File "/home/egor/miniconda3/lib/python3.11/site-packages/wandb/sdk/internal/internal_api.py", line 345, in execute
    return self.client.execute(*args, **kwargs)  # type: ignore
           ^^^^^^^^^^^^^^^^^^^^^^^^^^^^^^^^^^^^
  File "/home/egor/miniconda3/lib/python3.11/site-packages/wandb/vendor/gql-0.2.0/wandb_gql/client.py", line 52, in execute
    result = self._get_result(document, *args, **kwargs)
             ^^^^^^^^^^^^^^^^^^^^^^^^^^^^^^^^^^^^^^^^^^^
  File "/home/egor/miniconda3/lib/python3.11/site-packages/wandb/vendor/gql-0.2.0/wandb_gql/client.py", line 60, in _get_result
    return self.transport.execute(document, *args, **kwargs)
           ^^^^^^^^^^^^^^^^^^^^^^^^^^^^^^^^^^^^^^^^^^^^^^^^^
  File "/home/egor/miniconda3/lib/python3.11/site-packages/wandb/sdk/lib/gql_request.py", line 59, in execute
    request.raise_for_status()
  File "/home/egor/miniconda3/lib/python3.11/site-packages/requests/models.py", line 1021, in raise_for_status
    raise HTTPError(http_error_msg, response=self)
requests.exceptions.HTTPError: 404 Client Error: Not Found for url: https://api.wandb.ai/graphql

During handling of the above exception, another exception occurred:

Traceback (most recent call last):
  File "/home/egor/miniconda3/lib/python3.11/site-packages/wandb/apis/normalize.py", line 41, in wrapper
    return func(*args, **kwargs)
           ^^^^^^^^^^^^^^^^^^^^^
  File "/home/egor/miniconda3/lib/python3.11/site-packages/wandb/sdk/internal/internal_api.py", line 2500, in upload_urls
    query_result = self.gql(
                   ^^^^^^^^^
  File "/home/egor/miniconda3/lib/python3.11/site-packages/wandb/sdk/internal/internal_api.py", line 317, in gql
    ret = self._retry_gql(
          ^^^^^^^^^^^^^^^^
  File "/home/egor/miniconda3/lib/python3.11/site-packages/wandb/sdk/lib/retry.py", line 131, in __call__
    result = self._call_fn(*args, **kwargs)
             ^^^^^^^^^^^^^^^^^^^^^^^^^^^^^^
  File "/home/egor/miniconda3/lib/python3.11/site-packages/wandb/sdk/internal/internal_api.py", line 352, in execute
    wandb.termerror(f"Error while calling W&B API: {error} ({response})")
  File "/home/egor/miniconda3/lib/python3.11/site-packages/wandb/errors/term.py", line 64, in termerror
    _log(
  File "/home/egor/miniconda3/lib/python3.11/site-packages/wandb/errors/term.py", line 103, in _log
    click.echo(line, file=sys.stderr, nl=newline)
  File "/home/egor/miniconda3/lib/python3.11/site-packages/click/utils.py", line 318, in echo
    file.write(out)  # type: ignore
    ^^^^^^^^^^^^^^^
BrokenPipeError: [Errno 32] Broken pipe

During handling of the above exception, another exception occurred:

Traceback (most recent call last):
  File "/home/egor/miniconda3/lib/python3.11/concurrent/futures/thread.py", line 58, in run
    result = self.fn(*self.args, **self.kwargs)
             ^^^^^^^^^^^^^^^^^^^^^^^^^^^^^^^^^^
  File "/home/egor/miniconda3/lib/python3.11/site-packages/wandb/filesync/step_upload.py", line 223, in run_and_notify
    self._do_upload(event)
  File "/home/egor/miniconda3/lib/python3.11/site-packages/wandb/filesync/step_upload.py", line 243, in _do_upload
    job.run()
  File "/home/egor/miniconda3/lib/python3.11/site-packages/wandb/filesync/upload_job.py", line 56, in run
    self.push()
  File "/home/egor/miniconda3/lib/python3.11/site-packages/wandb/filesync/upload_job.py", line 105, in push
    _, upload_headers, result = self._api.upload_urls(project, [self.save_name])
                                ^^^^^^^^^^^^^^^^^^^^^^^^^^^^^^^^^^^^^^^^^^^^^^^^
  File "/home/egor/miniconda3/lib/python3.11/site-packages/wandb/apis/normalize.py", line 87, in wrapper
    raise CommError(message, err).with_traceback(sys.exc_info()[2])
  File "/home/egor/miniconda3/lib/python3.11/site-packages/wandb/apis/normalize.py", line 41, in wrapper
    return func(*args, **kwargs)
           ^^^^^^^^^^^^^^^^^^^^^
  File "/home/egor/miniconda3/lib/python3.11/site-packages/wandb/sdk/internal/internal_api.py", line 2500, in upload_urls
    query_result = self.gql(
                   ^^^^^^^^^
  File "/home/egor/miniconda3/lib/python3.11/site-packages/wandb/sdk/internal/internal_api.py", line 317, in gql
    ret = self._retry_gql(
          ^^^^^^^^^^^^^^^^
  File "/home/egor/miniconda3/lib/python3.11/site-packages/wandb/sdk/lib/retry.py", line 131, in __call__
    result = self._call_fn(*args, **kwargs)
             ^^^^^^^^^^^^^^^^^^^^^^^^^^^^^^
  File "/home/egor/miniconda3/lib/python3.11/site-packages/wandb/sdk/internal/internal_api.py", line 352, in execute
    wandb.termerror(f"Error while calling W&B API: {error} ({response})")
  File "/home/egor/miniconda3/lib/python3.11/site-packages/wandb/errors/term.py", line 64, in termerror
    _log(
  File "/home/egor/miniconda3/lib/python3.11/site-packages/wandb/errors/term.py", line 103, in _log
    click.echo(line, file=sys.stderr, nl=newline)
  File "/home/egor/miniconda3/lib/python3.11/site-packages/click/utils.py", line 318, in echo
    file.write(out)  # type: ignore
    ^^^^^^^^^^^^^^^
wandb.errors.CommError: [Errno 32] Broken pipe
2024-09-29 14:37:29,323 ERROR   wandb-upload_1:20028 [internal_api.py:execute():349] 404 response executing GraphQL.
2024-09-29 14:37:29,327 ERROR   wandb-upload_1:20028 [internal_api.py:execute():350] {"errors":[{"message":"run loss_choice_02/qt2c1omz not found during createRunFiles","path":["createRunFiles"]}],"data":{"createRunFiles":null}}
2024-09-29 14:37:29,327 ERROR   Thread-11 (_thread_body):20028 [step_upload.py:_handle_event():144] Failed to upload file: /home/egor/desktop/tmp/precondnn/exps/loss_choice_exps/exp02/wandb/run-20240929_143638-qt2c1omz/files/wandb-summary.json
Traceback (most recent call last):
  File "/home/egor/miniconda3/lib/python3.11/site-packages/wandb/sdk/internal/internal_api.py", line 345, in execute
    return self.client.execute(*args, **kwargs)  # type: ignore
           ^^^^^^^^^^^^^^^^^^^^^^^^^^^^^^^^^^^^
  File "/home/egor/miniconda3/lib/python3.11/site-packages/wandb/vendor/gql-0.2.0/wandb_gql/client.py", line 52, in execute
    result = self._get_result(document, *args, **kwargs)
             ^^^^^^^^^^^^^^^^^^^^^^^^^^^^^^^^^^^^^^^^^^^
  File "/home/egor/miniconda3/lib/python3.11/site-packages/wandb/vendor/gql-0.2.0/wandb_gql/client.py", line 60, in _get_result
    return self.transport.execute(document, *args, **kwargs)
           ^^^^^^^^^^^^^^^^^^^^^^^^^^^^^^^^^^^^^^^^^^^^^^^^^
  File "/home/egor/miniconda3/lib/python3.11/site-packages/wandb/sdk/lib/gql_request.py", line 59, in execute
    request.raise_for_status()
  File "/home/egor/miniconda3/lib/python3.11/site-packages/requests/models.py", line 1021, in raise_for_status
    raise HTTPError(http_error_msg, response=self)
requests.exceptions.HTTPError: 404 Client Error: Not Found for url: https://api.wandb.ai/graphql

During handling of the above exception, another exception occurred:

Traceback (most recent call last):
  File "/home/egor/miniconda3/lib/python3.11/site-packages/wandb/apis/normalize.py", line 41, in wrapper
    return func(*args, **kwargs)
           ^^^^^^^^^^^^^^^^^^^^^
  File "/home/egor/miniconda3/lib/python3.11/site-packages/wandb/sdk/internal/internal_api.py", line 2500, in upload_urls
    query_result = self.gql(
                   ^^^^^^^^^
  File "/home/egor/miniconda3/lib/python3.11/site-packages/wandb/sdk/internal/internal_api.py", line 317, in gql
    ret = self._retry_gql(
          ^^^^^^^^^^^^^^^^
  File "/home/egor/miniconda3/lib/python3.11/site-packages/wandb/sdk/lib/retry.py", line 131, in __call__
    result = self._call_fn(*args, **kwargs)
             ^^^^^^^^^^^^^^^^^^^^^^^^^^^^^^
  File "/home/egor/miniconda3/lib/python3.11/site-packages/wandb/sdk/internal/internal_api.py", line 352, in execute
    wandb.termerror(f"Error while calling W&B API: {error} ({response})")
  File "/home/egor/miniconda3/lib/python3.11/site-packages/wandb/errors/term.py", line 64, in termerror
    _log(
  File "/home/egor/miniconda3/lib/python3.11/site-packages/wandb/errors/term.py", line 103, in _log
    click.echo(line, file=sys.stderr, nl=newline)
  File "/home/egor/miniconda3/lib/python3.11/site-packages/click/utils.py", line 318, in echo
    file.write(out)  # type: ignore
    ^^^^^^^^^^^^^^^
BrokenPipeError: [Errno 32] Broken pipe

During handling of the above exception, another exception occurred:

Traceback (most recent call last):
  File "/home/egor/miniconda3/lib/python3.11/concurrent/futures/thread.py", line 58, in run
    result = self.fn(*self.args, **self.kwargs)
             ^^^^^^^^^^^^^^^^^^^^^^^^^^^^^^^^^^
  File "/home/egor/miniconda3/lib/python3.11/site-packages/wandb/filesync/step_upload.py", line 223, in run_and_notify
    self._do_upload(event)
  File "/home/egor/miniconda3/lib/python3.11/site-packages/wandb/filesync/step_upload.py", line 243, in _do_upload
    job.run()
  File "/home/egor/miniconda3/lib/python3.11/site-packages/wandb/filesync/upload_job.py", line 56, in run
    self.push()
  File "/home/egor/miniconda3/lib/python3.11/site-packages/wandb/filesync/upload_job.py", line 105, in push
    _, upload_headers, result = self._api.upload_urls(project, [self.save_name])
                                ^^^^^^^^^^^^^^^^^^^^^^^^^^^^^^^^^^^^^^^^^^^^^^^^
  File "/home/egor/miniconda3/lib/python3.11/site-packages/wandb/apis/normalize.py", line 87, in wrapper
    raise CommError(message, err).with_traceback(sys.exc_info()[2])
  File "/home/egor/miniconda3/lib/python3.11/site-packages/wandb/apis/normalize.py", line 41, in wrapper
    return func(*args, **kwargs)
           ^^^^^^^^^^^^^^^^^^^^^
  File "/home/egor/miniconda3/lib/python3.11/site-packages/wandb/sdk/internal/internal_api.py", line 2500, in upload_urls
    query_result = self.gql(
                   ^^^^^^^^^
  File "/home/egor/miniconda3/lib/python3.11/site-packages/wandb/sdk/internal/internal_api.py", line 317, in gql
    ret = self._retry_gql(
          ^^^^^^^^^^^^^^^^
  File "/home/egor/miniconda3/lib/python3.11/site-packages/wandb/sdk/lib/retry.py", line 131, in __call__
    result = self._call_fn(*args, **kwargs)
             ^^^^^^^^^^^^^^^^^^^^^^^^^^^^^^
  File "/home/egor/miniconda3/lib/python3.11/site-packages/wandb/sdk/internal/internal_api.py", line 352, in execute
    wandb.termerror(f"Error while calling W&B API: {error} ({response})")
  File "/home/egor/miniconda3/lib/python3.11/site-packages/wandb/errors/term.py", line 64, in termerror
    _log(
  File "/home/egor/miniconda3/lib/python3.11/site-packages/wandb/errors/term.py", line 103, in _log
    click.echo(line, file=sys.stderr, nl=newline)
  File "/home/egor/miniconda3/lib/python3.11/site-packages/click/utils.py", line 318, in echo
    file.write(out)  # type: ignore
    ^^^^^^^^^^^^^^^
wandb.errors.CommError: [Errno 32] Broken pipe
2024-09-29 14:37:29,422 ERROR   wandb-upload_2:20028 [internal_api.py:execute():349] 404 response executing GraphQL.
2024-09-29 14:37:29,422 ERROR   wandb-upload_2:20028 [internal_api.py:execute():350] {"errors":[{"message":"run loss_choice_02/qt2c1omz not found during createRunFiles","path":["createRunFiles"]}],"data":{"createRunFiles":null}}
2024-09-29 14:37:29,422 ERROR   Thread-11 (_thread_body):20028 [step_upload.py:_handle_event():144] Failed to upload file: /home/egor/desktop/tmp/precondnn/exps/loss_choice_exps/exp02/wandb/run-20240929_143638-qt2c1omz/files/config.yaml
Traceback (most recent call last):
  File "/home/egor/miniconda3/lib/python3.11/site-packages/wandb/sdk/internal/internal_api.py", line 345, in execute
    return self.client.execute(*args, **kwargs)  # type: ignore
           ^^^^^^^^^^^^^^^^^^^^^^^^^^^^^^^^^^^^
  File "/home/egor/miniconda3/lib/python3.11/site-packages/wandb/vendor/gql-0.2.0/wandb_gql/client.py", line 52, in execute
    result = self._get_result(document, *args, **kwargs)
             ^^^^^^^^^^^^^^^^^^^^^^^^^^^^^^^^^^^^^^^^^^^
  File "/home/egor/miniconda3/lib/python3.11/site-packages/wandb/vendor/gql-0.2.0/wandb_gql/client.py", line 60, in _get_result
    return self.transport.execute(document, *args, **kwargs)
           ^^^^^^^^^^^^^^^^^^^^^^^^^^^^^^^^^^^^^^^^^^^^^^^^^
  File "/home/egor/miniconda3/lib/python3.11/site-packages/wandb/sdk/lib/gql_request.py", line 59, in execute
    request.raise_for_status()
  File "/home/egor/miniconda3/lib/python3.11/site-packages/requests/models.py", line 1021, in raise_for_status
    raise HTTPError(http_error_msg, response=self)
requests.exceptions.HTTPError: 404 Client Error: Not Found for url: https://api.wandb.ai/graphql

During handling of the above exception, another exception occurred:

Traceback (most recent call last):
  File "/home/egor/miniconda3/lib/python3.11/site-packages/wandb/apis/normalize.py", line 41, in wrapper
    return func(*args, **kwargs)
           ^^^^^^^^^^^^^^^^^^^^^
  File "/home/egor/miniconda3/lib/python3.11/site-packages/wandb/sdk/internal/internal_api.py", line 2500, in upload_urls
    query_result = self.gql(
                   ^^^^^^^^^
  File "/home/egor/miniconda3/lib/python3.11/site-packages/wandb/sdk/internal/internal_api.py", line 317, in gql
    ret = self._retry_gql(
          ^^^^^^^^^^^^^^^^
  File "/home/egor/miniconda3/lib/python3.11/site-packages/wandb/sdk/lib/retry.py", line 131, in __call__
    result = self._call_fn(*args, **kwargs)
             ^^^^^^^^^^^^^^^^^^^^^^^^^^^^^^
  File "/home/egor/miniconda3/lib/python3.11/site-packages/wandb/sdk/internal/internal_api.py", line 352, in execute
    wandb.termerror(f"Error while calling W&B API: {error} ({response})")
  File "/home/egor/miniconda3/lib/python3.11/site-packages/wandb/errors/term.py", line 64, in termerror
    _log(
  File "/home/egor/miniconda3/lib/python3.11/site-packages/wandb/errors/term.py", line 103, in _log
    click.echo(line, file=sys.stderr, nl=newline)
  File "/home/egor/miniconda3/lib/python3.11/site-packages/click/utils.py", line 318, in echo
    file.write(out)  # type: ignore
    ^^^^^^^^^^^^^^^
BrokenPipeError: [Errno 32] Broken pipe

During handling of the above exception, another exception occurred:

Traceback (most recent call last):
  File "/home/egor/miniconda3/lib/python3.11/concurrent/futures/thread.py", line 58, in run
    result = self.fn(*self.args, **self.kwargs)
             ^^^^^^^^^^^^^^^^^^^^^^^^^^^^^^^^^^
  File "/home/egor/miniconda3/lib/python3.11/site-packages/wandb/filesync/step_upload.py", line 223, in run_and_notify
    self._do_upload(event)
  File "/home/egor/miniconda3/lib/python3.11/site-packages/wandb/filesync/step_upload.py", line 243, in _do_upload
    job.run()
  File "/home/egor/miniconda3/lib/python3.11/site-packages/wandb/filesync/upload_job.py", line 56, in run
    self.push()
  File "/home/egor/miniconda3/lib/python3.11/site-packages/wandb/filesync/upload_job.py", line 105, in push
    _, upload_headers, result = self._api.upload_urls(project, [self.save_name])
                                ^^^^^^^^^^^^^^^^^^^^^^^^^^^^^^^^^^^^^^^^^^^^^^^^
  File "/home/egor/miniconda3/lib/python3.11/site-packages/wandb/apis/normalize.py", line 87, in wrapper
    raise CommError(message, err).with_traceback(sys.exc_info()[2])
  File "/home/egor/miniconda3/lib/python3.11/site-packages/wandb/apis/normalize.py", line 41, in wrapper
    return func(*args, **kwargs)
           ^^^^^^^^^^^^^^^^^^^^^
  File "/home/egor/miniconda3/lib/python3.11/site-packages/wandb/sdk/internal/internal_api.py", line 2500, in upload_urls
    query_result = self.gql(
                   ^^^^^^^^^
  File "/home/egor/miniconda3/lib/python3.11/site-packages/wandb/sdk/internal/internal_api.py", line 317, in gql
    ret = self._retry_gql(
          ^^^^^^^^^^^^^^^^
  File "/home/egor/miniconda3/lib/python3.11/site-packages/wandb/sdk/lib/retry.py", line 131, in __call__
    result = self._call_fn(*args, **kwargs)
             ^^^^^^^^^^^^^^^^^^^^^^^^^^^^^^
  File "/home/egor/miniconda3/lib/python3.11/site-packages/wandb/sdk/internal/internal_api.py", line 352, in execute
    wandb.termerror(f"Error while calling W&B API: {error} ({response})")
  File "/home/egor/miniconda3/lib/python3.11/site-packages/wandb/errors/term.py", line 64, in termerror
    _log(
  File "/home/egor/miniconda3/lib/python3.11/site-packages/wandb/errors/term.py", line 103, in _log
    click.echo(line, file=sys.stderr, nl=newline)
  File "/home/egor/miniconda3/lib/python3.11/site-packages/click/utils.py", line 318, in echo
    file.write(out)  # type: ignore
    ^^^^^^^^^^^^^^^
wandb.errors.CommError: [Errno 32] Broken pipe
2024-09-29 14:37:29,453 ERROR   wandb-upload_4:20028 [internal_api.py:execute():349] 404 response executing GraphQL.
2024-09-29 14:37:29,454 ERROR   wandb-upload_4:20028 [internal_api.py:execute():350] {"errors":[{"message":"run loss_choice_02/qt2c1omz not found during createRunFiles","path":["createRunFiles"]}],"data":{"createRunFiles":null}}
2024-09-29 14:37:29,454 ERROR   Thread-11 (_thread_body):20028 [step_upload.py:_handle_event():144] Failed to upload file: /home/egor/desktop/tmp/precondnn/exps/loss_choice_exps/exp02/wandb/run-20240929_143638-qt2c1omz/files/conda-environment.yaml
Traceback (most recent call last):
  File "/home/egor/miniconda3/lib/python3.11/site-packages/wandb/sdk/internal/internal_api.py", line 345, in execute
    return self.client.execute(*args, **kwargs)  # type: ignore
           ^^^^^^^^^^^^^^^^^^^^^^^^^^^^^^^^^^^^
  File "/home/egor/miniconda3/lib/python3.11/site-packages/wandb/vendor/gql-0.2.0/wandb_gql/client.py", line 52, in execute
    result = self._get_result(document, *args, **kwargs)
             ^^^^^^^^^^^^^^^^^^^^^^^^^^^^^^^^^^^^^^^^^^^
  File "/home/egor/miniconda3/lib/python3.11/site-packages/wandb/vendor/gql-0.2.0/wandb_gql/client.py", line 60, in _get_result
    return self.transport.execute(document, *args, **kwargs)
           ^^^^^^^^^^^^^^^^^^^^^^^^^^^^^^^^^^^^^^^^^^^^^^^^^
  File "/home/egor/miniconda3/lib/python3.11/site-packages/wandb/sdk/lib/gql_request.py", line 59, in execute
    request.raise_for_status()
  File "/home/egor/miniconda3/lib/python3.11/site-packages/requests/models.py", line 1021, in raise_for_status
    raise HTTPError(http_error_msg, response=self)
requests.exceptions.HTTPError: 404 Client Error: Not Found for url: https://api.wandb.ai/graphql

During handling of the above exception, another exception occurred:

Traceback (most recent call last):
  File "/home/egor/miniconda3/lib/python3.11/site-packages/wandb/apis/normalize.py", line 41, in wrapper
    return func(*args, **kwargs)
           ^^^^^^^^^^^^^^^^^^^^^
  File "/home/egor/miniconda3/lib/python3.11/site-packages/wandb/sdk/internal/internal_api.py", line 2500, in upload_urls
    query_result = self.gql(
                   ^^^^^^^^^
  File "/home/egor/miniconda3/lib/python3.11/site-packages/wandb/sdk/internal/internal_api.py", line 317, in gql
    ret = self._retry_gql(
          ^^^^^^^^^^^^^^^^
  File "/home/egor/miniconda3/lib/python3.11/site-packages/wandb/sdk/lib/retry.py", line 131, in __call__
    result = self._call_fn(*args, **kwargs)
             ^^^^^^^^^^^^^^^^^^^^^^^^^^^^^^
  File "/home/egor/miniconda3/lib/python3.11/site-packages/wandb/sdk/internal/internal_api.py", line 352, in execute
    wandb.termerror(f"Error while calling W&B API: {error} ({response})")
  File "/home/egor/miniconda3/lib/python3.11/site-packages/wandb/errors/term.py", line 64, in termerror
    _log(
  File "/home/egor/miniconda3/lib/python3.11/site-packages/wandb/errors/term.py", line 103, in _log
    click.echo(line, file=sys.stderr, nl=newline)
  File "/home/egor/miniconda3/lib/python3.11/site-packages/click/utils.py", line 318, in echo
    file.write(out)  # type: ignore
    ^^^^^^^^^^^^^^^
BrokenPipeError: [Errno 32] Broken pipe

During handling of the above exception, another exception occurred:

Traceback (most recent call last):
  File "/home/egor/miniconda3/lib/python3.11/concurrent/futures/thread.py", line 58, in run
    result = self.fn(*self.args, **self.kwargs)
             ^^^^^^^^^^^^^^^^^^^^^^^^^^^^^^^^^^
  File "/home/egor/miniconda3/lib/python3.11/site-packages/wandb/filesync/step_upload.py", line 223, in run_and_notify
    self._do_upload(event)
  File "/home/egor/miniconda3/lib/python3.11/site-packages/wandb/filesync/step_upload.py", line 243, in _do_upload
    job.run()
  File "/home/egor/miniconda3/lib/python3.11/site-packages/wandb/filesync/upload_job.py", line 56, in run
    self.push()
  File "/home/egor/miniconda3/lib/python3.11/site-packages/wandb/filesync/upload_job.py", line 105, in push
    _, upload_headers, result = self._api.upload_urls(project, [self.save_name])
                                ^^^^^^^^^^^^^^^^^^^^^^^^^^^^^^^^^^^^^^^^^^^^^^^^
  File "/home/egor/miniconda3/lib/python3.11/site-packages/wandb/apis/normalize.py", line 87, in wrapper
    raise CommError(message, err).with_traceback(sys.exc_info()[2])
  File "/home/egor/miniconda3/lib/python3.11/site-packages/wandb/apis/normalize.py", line 41, in wrapper
    return func(*args, **kwargs)
           ^^^^^^^^^^^^^^^^^^^^^
  File "/home/egor/miniconda3/lib/python3.11/site-packages/wandb/sdk/internal/internal_api.py", line 2500, in upload_urls
    query_result = self.gql(
                   ^^^^^^^^^
  File "/home/egor/miniconda3/lib/python3.11/site-packages/wandb/sdk/internal/internal_api.py", line 317, in gql
    ret = self._retry_gql(
          ^^^^^^^^^^^^^^^^
  File "/home/egor/miniconda3/lib/python3.11/site-packages/wandb/sdk/lib/retry.py", line 131, in __call__
    result = self._call_fn(*args, **kwargs)
             ^^^^^^^^^^^^^^^^^^^^^^^^^^^^^^
  File "/home/egor/miniconda3/lib/python3.11/site-packages/wandb/sdk/internal/internal_api.py", line 352, in execute
    wandb.termerror(f"Error while calling W&B API: {error} ({response})")
  File "/home/egor/miniconda3/lib/python3.11/site-packages/wandb/errors/term.py", line 64, in termerror
    _log(
  File "/home/egor/miniconda3/lib/python3.11/site-packages/wandb/errors/term.py", line 103, in _log
    click.echo(line, file=sys.stderr, nl=newline)
  File "/home/egor/miniconda3/lib/python3.11/site-packages/click/utils.py", line 318, in echo
    file.write(out)  # type: ignore
    ^^^^^^^^^^^^^^^
wandb.errors.CommError: [Errno 32] Broken pipe
2024-09-29 14:37:29,470 ERROR   wandb-upload_3:20028 [internal_api.py:execute():349] 404 response executing GraphQL.
2024-09-29 14:37:29,470 ERROR   wandb-upload_3:20028 [internal_api.py:execute():350] {"errors":[{"message":"run loss_choice_02/qt2c1omz not found during createRunFiles","path":["createRunFiles"]}],"data":{"createRunFiles":null}}
2024-09-29 14:37:29,470 ERROR   Thread-11 (_thread_body):20028 [step_upload.py:_handle_event():144] Failed to upload file: /home/egor/desktop/tmp/precondnn/exps/loss_choice_exps/exp02/wandb/run-20240929_143638-qt2c1omz/files/requirements.txt
Traceback (most recent call last):
  File "/home/egor/miniconda3/lib/python3.11/site-packages/wandb/sdk/internal/internal_api.py", line 345, in execute
    return self.client.execute(*args, **kwargs)  # type: ignore
           ^^^^^^^^^^^^^^^^^^^^^^^^^^^^^^^^^^^^
  File "/home/egor/miniconda3/lib/python3.11/site-packages/wandb/vendor/gql-0.2.0/wandb_gql/client.py", line 52, in execute
    result = self._get_result(document, *args, **kwargs)
             ^^^^^^^^^^^^^^^^^^^^^^^^^^^^^^^^^^^^^^^^^^^
  File "/home/egor/miniconda3/lib/python3.11/site-packages/wandb/vendor/gql-0.2.0/wandb_gql/client.py", line 60, in _get_result
    return self.transport.execute(document, *args, **kwargs)
           ^^^^^^^^^^^^^^^^^^^^^^^^^^^^^^^^^^^^^^^^^^^^^^^^^
  File "/home/egor/miniconda3/lib/python3.11/site-packages/wandb/sdk/lib/gql_request.py", line 59, in execute
    request.raise_for_status()
  File "/home/egor/miniconda3/lib/python3.11/site-packages/requests/models.py", line 1021, in raise_for_status
    raise HTTPError(http_error_msg, response=self)
requests.exceptions.HTTPError: 404 Client Error: Not Found for url: https://api.wandb.ai/graphql

During handling of the above exception, another exception occurred:

Traceback (most recent call last):
  File "/home/egor/miniconda3/lib/python3.11/site-packages/wandb/apis/normalize.py", line 41, in wrapper
    return func(*args, **kwargs)
           ^^^^^^^^^^^^^^^^^^^^^
  File "/home/egor/miniconda3/lib/python3.11/site-packages/wandb/sdk/internal/internal_api.py", line 2500, in upload_urls
    query_result = self.gql(
                   ^^^^^^^^^
  File "/home/egor/miniconda3/lib/python3.11/site-packages/wandb/sdk/internal/internal_api.py", line 317, in gql
    ret = self._retry_gql(
          ^^^^^^^^^^^^^^^^
  File "/home/egor/miniconda3/lib/python3.11/site-packages/wandb/sdk/lib/retry.py", line 131, in __call__
    result = self._call_fn(*args, **kwargs)
             ^^^^^^^^^^^^^^^^^^^^^^^^^^^^^^
  File "/home/egor/miniconda3/lib/python3.11/site-packages/wandb/sdk/internal/internal_api.py", line 352, in execute
    wandb.termerror(f"Error while calling W&B API: {error} ({response})")
  File "/home/egor/miniconda3/lib/python3.11/site-packages/wandb/errors/term.py", line 64, in termerror
    _log(
  File "/home/egor/miniconda3/lib/python3.11/site-packages/wandb/errors/term.py", line 103, in _log
    click.echo(line, file=sys.stderr, nl=newline)
  File "/home/egor/miniconda3/lib/python3.11/site-packages/click/utils.py", line 318, in echo
    file.write(out)  # type: ignore
    ^^^^^^^^^^^^^^^
BrokenPipeError: [Errno 32] Broken pipe

During handling of the above exception, another exception occurred:

Traceback (most recent call last):
  File "/home/egor/miniconda3/lib/python3.11/concurrent/futures/thread.py", line 58, in run
    result = self.fn(*self.args, **self.kwargs)
             ^^^^^^^^^^^^^^^^^^^^^^^^^^^^^^^^^^
  File "/home/egor/miniconda3/lib/python3.11/site-packages/wandb/filesync/step_upload.py", line 223, in run_and_notify
    self._do_upload(event)
  File "/home/egor/miniconda3/lib/python3.11/site-packages/wandb/filesync/step_upload.py", line 243, in _do_upload
    job.run()
  File "/home/egor/miniconda3/lib/python3.11/site-packages/wandb/filesync/upload_job.py", line 56, in run
    self.push()
  File "/home/egor/miniconda3/lib/python3.11/site-packages/wandb/filesync/upload_job.py", line 105, in push
    _, upload_headers, result = self._api.upload_urls(project, [self.save_name])
                                ^^^^^^^^^^^^^^^^^^^^^^^^^^^^^^^^^^^^^^^^^^^^^^^^
  File "/home/egor/miniconda3/lib/python3.11/site-packages/wandb/apis/normalize.py", line 87, in wrapper
    raise CommError(message, err).with_traceback(sys.exc_info()[2])
  File "/home/egor/miniconda3/lib/python3.11/site-packages/wandb/apis/normalize.py", line 41, in wrapper
    return func(*args, **kwargs)
           ^^^^^^^^^^^^^^^^^^^^^
  File "/home/egor/miniconda3/lib/python3.11/site-packages/wandb/sdk/internal/internal_api.py", line 2500, in upload_urls
    query_result = self.gql(
                   ^^^^^^^^^
  File "/home/egor/miniconda3/lib/python3.11/site-packages/wandb/sdk/internal/internal_api.py", line 317, in gql
    ret = self._retry_gql(
          ^^^^^^^^^^^^^^^^
  File "/home/egor/miniconda3/lib/python3.11/site-packages/wandb/sdk/lib/retry.py", line 131, in __call__
    result = self._call_fn(*args, **kwargs)
             ^^^^^^^^^^^^^^^^^^^^^^^^^^^^^^
  File "/home/egor/miniconda3/lib/python3.11/site-packages/wandb/sdk/internal/internal_api.py", line 352, in execute
    wandb.termerror(f"Error while calling W&B API: {error} ({response})")
  File "/home/egor/miniconda3/lib/python3.11/site-packages/wandb/errors/term.py", line 64, in termerror
    _log(
  File "/home/egor/miniconda3/lib/python3.11/site-packages/wandb/errors/term.py", line 103, in _log
    click.echo(line, file=sys.stderr, nl=newline)
  File "/home/egor/miniconda3/lib/python3.11/site-packages/click/utils.py", line 318, in echo
    file.write(out)  # type: ignore
    ^^^^^^^^^^^^^^^
wandb.errors.CommError: [Errno 32] Broken pipe
2024-09-29 14:37:29,674 INFO    Thread-11 (_thread_body):20028 [sender.py:transition_state():626] send defer: 11
2024-09-29 14:37:29,675 DEBUG   HandlerThread:20028 [handler.py:handle_request():158] handle_request: defer
2024-09-29 14:37:29,675 INFO    HandlerThread:20028 [handler.py:handle_request_defer():184] handle defer: 11
2024-09-29 14:37:29,676 DEBUG   SenderThread:20028 [sender.py:send_request():418] send_request: defer
2024-09-29 14:37:29,676 INFO    SenderThread:20028 [sender.py:send_request_defer():622] handle sender defer: 11
2024-09-29 14:37:29,676 INFO    SenderThread:20028 [file_pusher.py:join():175] waiting for file pusher
2024-09-29 14:37:29,676 INFO    SenderThread:20028 [sender.py:transition_state():626] send defer: 12
2024-09-29 14:37:29,676 DEBUG   HandlerThread:20028 [handler.py:handle_request():158] handle_request: defer
2024-09-29 14:37:29,676 INFO    HandlerThread:20028 [handler.py:handle_request_defer():184] handle defer: 12
2024-09-29 14:37:29,677 DEBUG   SenderThread:20028 [sender.py:send_request():418] send_request: defer
2024-09-29 14:37:29,677 INFO    SenderThread:20028 [sender.py:send_request_defer():622] handle sender defer: 12
2024-09-29 14:37:29,677 INFO    SenderThread:20028 [file_stream.py:finish():601] file stream finish called
2024-09-29 14:37:29,677 INFO    SenderThread:20028 [file_stream.py:finish():605] file stream finish is done
2024-09-29 14:37:29,677 ERROR   SenderThread:20028 [file_stream.py:finish():607] FileStream exception
Traceback (most recent call last):
  File "/home/egor/miniconda3/lib/python3.11/site-packages/wandb/sdk/internal/file_stream.py", line 496, in _thread_except_body
    self._thread_body()
  File "/home/egor/miniconda3/lib/python3.11/site-packages/wandb/sdk/internal/file_stream.py", line 452, in _thread_body
    success = self._send(ready_chunks, uploaded=uploaded)
              ^^^^^^^^^^^^^^^^^^^^^^^^^^^^^^^^^^^^^^^^^^^
  File "/home/egor/miniconda3/lib/python3.11/site-packages/wandb/sdk/internal/file_stream.py", line 541, in _send
    self._handle_response(
  File "/home/egor/miniconda3/lib/python3.11/site-packages/wandb/sdk/internal/file_stream.py", line 507, in _handle_response
    wandb.termerror(
  File "/home/egor/miniconda3/lib/python3.11/site-packages/wandb/errors/term.py", line 64, in termerror
    _log(
  File "/home/egor/miniconda3/lib/python3.11/site-packages/wandb/errors/term.py", line 103, in _log
    click.echo(line, file=sys.stderr, nl=newline)
  File "/home/egor/miniconda3/lib/python3.11/site-packages/click/utils.py", line 318, in echo
    file.write(out)  # type: ignore
    ^^^^^^^^^^^^^^^
BrokenPipeError: [Errno 32] Broken pipe
2024-09-29 14:37:30,112 DEBUG   HandlerThread:20028 [handler.py:handle_request():158] handle_request: poll_exit
2024-09-29 14:37:30,112 INFO    HandlerThread:20028 [handler.py:finish():884] shutting down handler
2024-09-29 14:37:30,112 INFO    WriterThread:20028 [datastore.py:close():296] close: /home/egor/desktop/tmp/precondnn/exps/loss_choice_exps/exp02/wandb/run-20240929_143638-qt2c1omz/run-qt2c1omz.wandb
2024-09-29 14:37:30,454 ERROR   StreamThr :20028 [internal.py:wandb_internal():173] Thread SenderThread:
Traceback (most recent call last):
  File "/home/egor/miniconda3/lib/python3.11/site-packages/wandb/sdk/internal/internal_util.py", line 48, in run
    self._run()
  File "/home/egor/miniconda3/lib/python3.11/site-packages/wandb/sdk/internal/internal_util.py", line 99, in _run
    self._process(record)
  File "/home/egor/miniconda3/lib/python3.11/site-packages/wandb/sdk/internal/internal.py", line 327, in _process
    self._sm.send(record)
  File "/home/egor/miniconda3/lib/python3.11/site-packages/wandb/sdk/internal/sender.py", line 398, in send
    send_handler(record)
  File "/home/egor/miniconda3/lib/python3.11/site-packages/wandb/sdk/internal/sender.py", line 420, in send_request
    send_handler(record)
  File "/home/egor/miniconda3/lib/python3.11/site-packages/wandb/sdk/internal/sender.py", line 677, in send_request_defer
    self._fs.finish(self._exit_code)
  File "/home/egor/miniconda3/lib/python3.11/site-packages/wandb/sdk/internal/file_stream.py", line 610, in finish
    raise self._exc_info[1].with_traceback(self._exc_info[2])
  File "/home/egor/miniconda3/lib/python3.11/site-packages/wandb/sdk/internal/file_stream.py", line 496, in _thread_except_body
    self._thread_body()
  File "/home/egor/miniconda3/lib/python3.11/site-packages/wandb/sdk/internal/file_stream.py", line 452, in _thread_body
    success = self._send(ready_chunks, uploaded=uploaded)
              ^^^^^^^^^^^^^^^^^^^^^^^^^^^^^^^^^^^^^^^^^^^
  File "/home/egor/miniconda3/lib/python3.11/site-packages/wandb/sdk/internal/file_stream.py", line 541, in _send
    self._handle_response(
  File "/home/egor/miniconda3/lib/python3.11/site-packages/wandb/sdk/internal/file_stream.py", line 507, in _handle_response
    wandb.termerror(
  File "/home/egor/miniconda3/lib/python3.11/site-packages/wandb/errors/term.py", line 64, in termerror
    _log(
  File "/home/egor/miniconda3/lib/python3.11/site-packages/wandb/errors/term.py", line 103, in _log
    click.echo(line, file=sys.stderr, nl=newline)
  File "/home/egor/miniconda3/lib/python3.11/site-packages/click/utils.py", line 318, in echo
    file.write(out)  # type: ignore
    ^^^^^^^^^^^^^^^
BrokenPipeError: [Errno 32] Broken pipe
